Workbook
Name afsfasfad: '[1]Coleta de Dados'!#REF!
Name afsfasfad: '[2]Coleta de Dados'!#REF!
Name afsfasfad: '[2]Coleta de Dados'!#REF!
Name Cabine15: '[1]Coleta de Dados'!$BF$7:$BF$1129
Name Cabine15: '[2]Coleta de Dados'!$BF$7:$BF$1129
Name Cabine32: '[1]Coleta de Dados'!$BL$7:$BL$1129
Name Cabine32: '[2]Coleta de Dados'!$BL$7:$BL$1129
Name Cabine85: '[1]Coleta de Dados'!$BG$7:$BG$1129
Name Cabine85: '[2]Coleta de Dados'!$BG$7:$BG$1129
Name CentrosdeCustos: [1]Consulta!$A$2:$E$30
Name CentrosdeCustos: [2]Consulta!$A$2:$E$30
Name Compressores: '[1]Coleta de Dados'!$BR$7:$BR$1129
Name Compressores: '[2]Coleta de Dados'!$BR$7:$BR$1129
Name Dados: '[1]Coleta de Dados'!$C$7:$Y$1129
Name Dados: '[2]Coleta de Dados'!$C$7:$Y$1129
Name DataTérmino: '[1]Coleta de Dados'!$W$7:$W$1129
Name DataTérmino: '[2]Coleta de Dados'!$W$7:$W$1129
Name DimecoConectores: '[1]Coleta de Dados'!$BV$7:$BV$1129
Name DimecoConectores: '[2]Coleta de Dados'!$BV$7:$BV$1129
Name DimecoTravesanos: '[1]Coleta de Dados'!$BI$7:$BI$1129
Name DimecoTravesanos: '[2]Coleta de Dados'!$BI$7:$BI$1129
Name DobradeiraSorg: '[1]Coleta de Dados'!$BU$7:$BU$1129
Name DobradeiraSorg: '[2]Coleta de Dados'!$BU$7:$BU$1129
Name Emissão: '[1]Coleta de Dados'!$AD$1:$AD$65536
Name Emissão: '[2]Coleta de Dados'!$AD$1:$AD$65536
Name Empilhadeiraelet: '[1]Coleta de Dados'!$CC$7:$CC$1129
Name Empilhadeiraelet: '[2]Coleta de Dados'!$CC$7:$CC$1129
Name Entradas: '[1]Coleta de Dados'!$F$7:$F$1129
Name Entradas: '[2]Coleta de Dados'!$F$7:$F$1129
Name Equipamentos: '[1]Coleta de Dados'!$H$7:$H$1129
Name Equipamentos: '[2]Coleta de Dados'!$H$7:$H$1129
Name Esmerilhadeira: '[1]Coleta de Dados'!$CD$7:$CD$1129
Name Esmerilhadeira: '[2]Coleta de Dados'!$CD$7:$CD$1129
Name FagorLargueros: '[1]Coleta de Dados'!$BM$7:$BM$1129
Name FagorLargueros: '[2]Coleta de Dados'!$BM$7:$BM$1129
Name FagorMontantes: '[1]Coleta de Dados'!$BJ$7:$BJ$1129
Name FagorMontantes: '[2]Coleta de Dados'!$BJ$7:$BJ$1129
Name Fresadora: '[1]Coleta de Dados'!$BT$7:$BT$1129
Name Fresadora: '[2]Coleta de Dados'!$BT$7:$BT$1129
Name FuradeiraColuna: '[1]Coleta de Dados'!$BS$7:$BS$1129
Name FuradeiraColuna: '[2]Coleta de Dados'!$BS$7:$BS$1129
Name Gasparini: '[1]Coleta de Dados'!$BN$7:$BN$1129
Name Gasparini: '[2]Coleta de Dados'!$BN$7:$BN$1129
Name GuilhotinaSorg: '[1]Coleta de Dados'!$BK$7:$BK$1129
Name GuilhotinaSorg: '[2]Coleta de Dados'!$BK$7:$BK$1129
Name imp: '[1]Coleta de Dados'!#REF!
Name imp: '[2]Coleta de Dados'!#REF!
Name imp: '[2]Coleta de Dados'!#REF!
Name Impressora: '[1]Coleta de Dados'!#REF!
Name Impressora: '[2]Coleta de Dados'!#REF!
Name Impressora: '[2]Coleta de Dados'!#REF!
Name LUIS: '[1]Coleta de Dados'!#REF!
Name LUIS: '[2]Coleta de Dados'!#REF!
Name MáqEmbalar: '[1]Coleta de Dados'!$CA$7:$CA$1129
Name MáqEmbalar: '[2]Coleta de Dados'!$CA$7:$CA$1129
Name Mês: '[1]Coleta de Dados'!$AB$7:$AB$1129
Name Mês: '[2]Coleta de Dados'!$AB$7:$AB$1129
Name MêsI: '[1]Coleta de Dados'!$AB$7:$AB$1129
Name MêsI: '[2]Coleta de Dados'!$AB$7:$AB$1129
Name MêsT: '[1]Coleta de Dados'!$AC$7:$AC$1129

Sheet CLIENTES
A1: REMED MEDICAL SERVICE | B1: INSTITUCIÓN
A2: ZENTRIA AVIDANTI | B2: MEDIASISTENCIA
A3: VidaNova IPS | B3: MEDICOL
A4: VIDAMEDICAL BOGOTA IPS SAS | B4: UNIANDES
A5: VANTIVE S.A.S. | B5: MEDICADIZ
A6: VALLESALUD | B6: MARIO GAITAN YANGUAS
A7: UNIVERSIDAD PONTIFICIA BOLIVARIANA | B7: MAGILAB S.A.S
A8: UNION TEMPORAL SERVISALUD SAN JOSE | B8: MAGISTRALES DE COLOMBIA
A9: UNION TEMPORAL RED VITAL | B9: LIGA CONTRA EL CANCER DE RISARALDA
A10: UNIDHOS IPS | B10: LA CASA DEL NIÑO
A11: UNIDAD DE ORIENTACION Y ASISTENCIA MATERNA | B11: LA CARDIO
A12: UNIANDES | B12: MACROMEDICOS
... A149: BOSTON MEDICAL | B149: BIO VIE S.A.S
A150: BIO VIE S.A.S | B150: BAXTER | D150: CENTRO ORIENTE | E150: SANTA CLARA | F150: SAN BLAS | G150: MATERNO SUR | H150: VICTORIA | I150: BRAVO PAEZ
A151: BAXTER | B151: AUDIFARMA | D151: NORTE | E151: SUBA | F151: ENGATIVA | G151: SIMON BOLIVAR
A152: AUDIFARMA | B152: ANDREA PERILLA | D152: SUB RED SUR OCCIDENTE | E152: KENNEDY
A153: ANGIOGRAFÍA DE COLOMBIA S.A. | B153: ONCOLOGIA DUMIAN CLINICA MARIANGEL
A154: REMED MEDICAL SERVICE | B154: HOSPITAL MARCO FIDEL SUAREZ DE BELLO | D154: SUB RED SUR | E154: TUNAL | F154: MEISEN | G154: VISTA HERMOSA
A155: CAJA DE COMPENSACION FAMILIAR DE CALDAS | B155: PROVIDA IPS
A156: SERVIMOS CAUCA | B156: RED VITAL DEL VALLE
A157: FARMART | B157: REINA SOFIA
A158: HOSPITAL ENGATIVA SUBRED NORTE | B158: RIESGO DE FRACTURA S.A - CAYRE
A159: HOSPITAL MEISSEN -SUBRED SUR | B159: RM SUMINISTROS UT
A160: HOSPITAL SUBA SUBRED NORTE | B160: RTS AGENCIA HUV
A161: DIACOR SOACHA ZONA FRANCA S A S | B161: RTS SANTA CLARA
A162: UMHES MATERNO INFANTIL SUBRED CENTRO ORIENTE | B162: RTS AGENCIA PALMIRA
A163: HACES INVERSIONES Y SERVICIOS S.A.S. | B163: RTS AGENCIA SANTA CLARA
A164: MESSER COLOMBIA S.A. | B164: RTS AGENCIA SUCURSAL POPAYAN
A165: CLINICA CHIA S A S | B165: RTS BARRANQUILLA
A166: HOSPITAL EL TUNAL -SUBRED SUR | B166: RTS CARDIOINFANTIL
... A191: CLINICA DEL CONTRY | B191: UNIDHOS IPS
B192: UNION TEMPORAL RED VIRTAL
B193: VALLE SALUD
B194: VIDAMEICA IPS
B195: LIGA CONTRA EL CÁNCER RISARALDA
B196: INSTITUTO ONCOLÓGICO DEL GRUPO OSPEDALE. INOOS
B197: FEMSALUD
B198: E.S.E HOSPITAL UNIVERSITARIO DE LA SAMARITANA - HOSPITAL REGIONAL DE ZIPAQUIRA
B199: SAN RAFAEL DE PEREIRA
B200: Clínica Avidanti Ciudad Verde
...

Sheet ATENCION 
L1: Pagina 1 de 1
B2: ATENCIÓN Y SEGUIMIENTO DE PQRS | L2: CÓDIGO: AC-FR-054-04
B4: DATOS DE RECEPCIÓN DE PQRS
B6: Fecha PQRS: | E6: 46122 | F6: Regional: | G6: LLANOS | J6: Solicitud N°: | L6: 130
B9: Hora de recepción | E9: 0.78888889 | F9: Medio de la queja | H9: E-MAIL
G10: Carta, E-mail, Telefono, Web, Personal
B11: Nombre del receptor de la PQRS | F11: SERVICIO AL CLIENTE
B14: DATOS DEL SOLICITANTE
E16: CLIENTE
E17: CLINICA PRIMAVERA LLANOS
E18: INSTITUCION
E19: CLINICA PRIMAVERA LLANOS
E20: CIUDAD
E21: VILLAVICENCIO
E22: NOMBRE Y CARGO DEL SOLICITANTE
E23: KAREN GINETH GUTIEREZ
E24: TELEFONO
E25: 3104606430
E26: CORREO ELECTRONICO
E27: QuimicoFCO@clinicaprimavera.com
B29: TIPO DE SOLICITUD
E31: QUEJA
E32: Sugerencia, Pregunta, Queja, Reclamo , Felicitación
B34: PROCESO RELACIONADO
F35: ,
B36: Tecnica | C36: x | E36: ENTREGA FUERA DEL ACUERDO DE SERVICIO | J36: ONCOLOGÍA
B38: Servicio | F38: TIPIFICACION | J38: Línea
H39: (NPT, Estériles, Oncología, No Esteriles, Magistral)
B40: DESCRIPCIÓN DE LA SOLICITUD
B41: Describa la situación citando hechos y datos ( Lote, Fecha, ID), teniendo en cuenta las siguientes preguntas: Qué? Quién? Dónde? Cuándo?
B42: Buen día, quisiera por medio de este correo reportar atrasos en la entrega de medicamentos de quimioterapia de los pacientes agendados para el día 08/04/2026, los cuales fueron citados 8 am y confirmados de manera oportuna, sin embargo siendo las 11+15 am no han sido entregada la OP, lo cual genera atrasos en los tratamientos de los pacientes, adicionalmente todos han manifestado inconformidad por lo sucedido.
G45: FECHA | H45: RESPONSABLE | J45: OBSERVACIONES
B46: Acuse de recibo de la queja al reclamante | G46: =E6 -> 46122
B47: Evaluación e investigación de la queja
B48: Solución de la queja
B49: Información al reclamante
B50: Verificación de las acciones
B51: La respuesta fue satisfactoria si no
B52: Cierre de la queja
B211: REMED MEDICAL SERVICE

Sheet ANALISIS
J1: Pagina 1 de 1
A2: ANÁLISIS E INVESTIGACIÓN DE PQRS | J2: CÓDIGO: AC-FR-055-04
A4: DATOS DE RECEPCIÓN DE PQRS
B6: Fecha PQRS: | D6: ='ATENCION '!E6 -> 46122 | F6: Regional: | G6: ='ATENCION '!G6:I6 -> LLANOS | I6: Solicitud N°: | J6: ='ATENCION '!L6 -> 130
D7: (dd/mm/aa)
A9: DESCRIPCIÓN DE LA SOLICITUD
A10: Describa la situación citando hechos y datos ( Lote, Fecha, ID), teniendo en cuenta las siguientes preguntas: Qué? Quién? Dónde? Cuándo?
A11: ='ATENCION '!B42 -> Buen día, quisiera por medio de este correo reportar atrasos en la entrega de medicamentos de quimioterapia de los pacientes agendados para el día 08/04/2026, los cuales fueron citados 8 am y confirmados de manera oportuna, sin embargo siendo las 11+15 am no han sido entregada la OP, lo cual genera atrasos en los tratamientos de los pacientes, adicionalmente todos han manifestado inconformidad por lo sucedido.
A17: INVESTIGACION
B19: Cliente / Institución
B20: ='ATENCION '!E17 -> CLINICA PRIMAVERA LLANOS
B21: Área o Proceso Involucrado en la investigación de la PQRS
B22: PRODUCCIÓN Y DIRECCIÓN TÉCNICA
B23: Responsable de la Investigación
B24: TATIANA RICO
B25: Cargo
B26: =VLOOKUP(B24,'RESPONSABLE '!A2:B40,2,0) -> DIRECTOR DE TECNICO REGIONA LLANOS
A28: CLASIFICACIÓN DE LA QUEJA
B30: MAYOR
E32: TÉCNICA : | F32: Critico, Mayor , Menor
C33: X | E33: POR SERVICIO: | F33: Imprescindible, Importante, Normal
A35: Causa del problema | F35: Que acción se va a realizar | H35: Quién será el responsable | J35: Fecha de Implementación
A42: OBSERVACIONES
B45: FECHA ENTREGA FORMATO | G45: VoBo Calidad

Sheet LISTADO MAESTRO
U1: Pagina 1 de 2
A2: LISTADO MAESTRO DE PQRS (BASE DIGITAL NACIONAL) | U2: CÓDIGO: AC-FR-056-04
A3: DATOS ENTREGADOS POR EL SOLICITANTE | J3: CLASIFICACIÓN INTERNA | O3: SEGUIMIENTO | U3: DATOS DEL CLIENTE
A4: ITEM | B4: CODIGO | C4: FECHA DE RECEPCIÓN | D4: MES | E4: REGIONAL | F4: CLIENTE | G4: INSTITUCION | H4: LÍNEA | I4: DESCRIPCIÓN | J4: TIPIFICACIÓN | K4: PROCEDE | L4: CLASIFICACIÓN | M4: PROCESO | N4: RESPONSABLE | O4: FECHA ENTREGA LÍDER | P4: FECHA RESPUESTA FINAL | Q4: ESTATUS 1 RESPUESTA | R4: FECHA VERIFICACIÓN ACCIONES | S4: ESTATUS 2 ACCIONES | T4: SOLICITUD RECIBIDA POR | U4: NOMBRE CONTACTO | V4: TELÉFONO | W4: CORREO ELECTRÓNICO E IMÁGENES | X4: ADJUNTOS | Y4: INVESTIGADAS
A5: 1 | B5: 001 | C5: 46031 | D5: ENERO | E5: CUNDINAMARCA | F5: SOCIEDAD DE CIRUGIA DE BOGOTA HOSPITAL DE SAN JOSE | G5: HOSPITAL INFANTIL UNIVERSITARIO SAN JOSE | H5: DOSIS ANTICIPADA | I5: Buenos dias. Con el presente documento quiero notificar que para el día 06/01/2026 no se ha recibido NINGUNA UNIDAD de Hidromorfona JP de la orden de producción enviada desde el martes 30/12/2025 y confirmada por ustedes el mismo día, según comunicación de ustedes se recibiría la orden el día 03/01/2026 no se brindo información oportuna sobre el retraso ni se respondió a las inquietudes expresadas, la inoportunidad de entrega genera dificultades para el cubrimiento de las necesidades de la IPS aumento el riesgo de acontecimiento de sucesos de seguridad, Esta situación también genera dificultades para la generación de la orden de producción de la semana del producto mencionado al cruzarse los requerimientos, teniendo en cuenta esto la orden será enviada el día 08/01/2026 con solicitud de llegada máximo el SÁBADO 10/01/2026 Dado lo anterior, se le solicita atentamente a Unidossis que se cumpla con los tiempos estipulados para no generar traumatismos en la operación de la IPS. | J5: ENTREGA FUERA DEL ACUERDO DE SERVICIO | K5: SI | L5: MAYOR | M5: PRODUCCIÓN Y DIRECCIÓN TÉCNICA | N5: MARTIN DURANGO | Q5: ABIERTA | S5: ABIERTA | T5: SERVICIO AL CLIENTE | U5: María Saavedra, Químico Farmacéutico | V5: 3538000 Ext. 468-422 | W5: rordenespro20211123@gmail.com | X5: ADJUNTOS | Y5: NO
A6: 1 | B6: 2 | C6: 46031 | D6: ENERO | E6: CUNDINAMARCA | F6: CHRISTUS SINERGIA | G6: CHRISTUS SINERGIA | H6: NPT | I6: Buen día. Espero se encuentren muy bien. Nos permitimos informar que el 05 de enero de 2026 se ingresaron durante la mañana las solicitudes de stocks, ajustes individualizados por pacientes y TPN. Posteriormente, en horas de la tarde, se nos comunicó que dichas solicitudes no habían sido consideradas debido a un atraso en la planta de producción. Esta situación obligó a que las modificaciones y preparaciones de dosis fueran realizadas directamente en las unidades de enfermería, alterando el flujo habitual de trabajo y generando un impacto en la organización del servicio farmacéutico. Adjunto a este correo el formato de PQR’s en el que se detalla la situación mencionada previamente. Agradecemos de antemano la atención prestada y solicitamos amablemente que se establezca un plan de acción que permita corregir y prevenir este tipo de inconvenientes en el futuro, garantizando así la eficiencia del trabajo conjunto. Quedo atenta a su respuesta. Muchas gracias. | J6: INCUMPLIMIENTO ACTIVIDADES O COMPROMISOS | K6: SI | L6: MAYOR | M6: PRODUCCIÓN Y DIRECCIÓN TÉCNICA | N6: MARTIN DURANGO | Q6: ABIERTA | S6: ABIERTA | T6: SERVICIO AL CLIENTE | U6: María Saavedra, Químico Farmacéutico | V6: N/R | W6: quimicofarmaceutico2.cpr@christus.co | X6: ADJUNTOS | Y6: NO
A7: 1 | B7: 3 | C7: 46031 | D7: ENERO | E7: CUNDINAMARCA | F7: HOSPITAL UNIVERSITARIO SAN IGNACIO | G7: HOSPITAL UNIVERSITARIO SAN IGNACIO | H7: ESTERILES | I7: Cordial saludo Unidossis, Se verifican los movimientos y se identifican las siguientes observaciones: Las unidades sobrantes de Heparinas (54 Nabuco y 52 en HUSI) corresponden a aprovechamientos tal como se verifico telefónicamente y por correo electrónico, por ende, se realizan los respectivos aprovechamientos internamente. Se identifican las siguientes novedades respecto a los movimientos de Bicarbonato: Solicitud Material Producción Fecha movimiento Código producto Descripción producto salida 25/12/2025 4057014 BICARBONATO DE SODIO 8,4% 10mEq/10ml SOL. INY. AMP IV 04057014 12 26/12/2025 4057014 BICARBONATO DE SODIO 8,4% 10mEq/10ml SOL. INY. AMP IV 04057014 1 Para el día (25/12/2025) se debían gastar (12) viales correspondientes a la preparación de 60 DUs de Bicarbonato de sodio (Se adjunta OP), sin embargo, el día (26/12/2025) se identifica la salida de (1) unidad, la cual no corresponde con ninguna preparación. Por favor solicitamos amablemente indicar a que corresponde esta unidad faltante de Bicarbonato de sodio, y si aplica, la respectiva nota crédito. Quedo atento a cualquier inquietud. Cordialmente, | J7: DIFERENCIA EN INVENTARIO EN CUSTODIA | K7: SI | L7: MAYOR | M7: PRODUCCIÓN Y DIRECCIÓN TÉCNICA | N7: MARTIN DURANGO | Q7: ABIERTA | S7: ABIERTA | T7: SERVICIO AL CLIENTE | U7: Yuri Alberto Echeverri Pineda Químico Farmacéutico Asistencial | V7: Teléfono: (601) 5946161 Ext. 3007 | W7: cytinoco@husiorgco.onmicrosoft.com | X7: ADJUNTOS | Y7: NO
A8: 1 | B8: 4 | C8: 46031 | D8: ENERO | E8: CUNDINAMARCA | F8: HOSPITAL UNIVERSITARIO CLINICA SAN RAFAEL | G8: HOSPITAL U SAN RAFAEL BOGOTA | H8: SOLIDOS | I8: Cordial saludo. Lo siguiente es para informar, que en el pedido enviado se recibió una producción de Solidos con la descripción de la razón social equivocada, por lo cual se solicita a ustedes verificar la información suministrada y hacer las correcciones pertinentes en futuras envíos de productos. Adjunto los datos correctos: Nombre: Clínica San Rafael alta complejidad Nit: 91089614-3 Direccion: calle 12 #27-100 Vía Clemente Salazar - Sabanalarga Atlántico | J8: ERROR EN ETIQUETA/CODIFICADO | K8: SI | L8: MAYOR | M8: PRODUCCIÓN Y DIRECCIÓN TÉCNICA | N8: DORIA NARVÁEZ REYES ENRIQUE | Q8: ABIERTA | S8: ABIERTA | T8: SERVICIO AL CLIENTE | U8: DIANA PADILLA BARRAZA | V8: Cel. 3105252900 Tel. (095)8784012 | W8: serviciofarmaceutico@csr.com.co | X8: ADJUNTOS | Y8: NO
A9: 1 | B9: 5 | C9: 46031 | D9: ENERO | E9: CUNDINAMARCA | F9: VIDAMEDICAL BOGOTA IPS SAS | G9: VIDAMEICA IPS | H9: ONCOLOGÍA | I9: Buenos días. Por medio del presente informo que el día 26/12/2025 se solicitó la preparación para la paciente MARIA MARTINA MATEUS VARGAS del medicamento TOCILIZUMAB 360 mg (ACTEMRA), quien tenía administración el día 27/12/2025. Estos medicamentos se enviaron el día viernes 26/12/2025 a Unidossis. El día 26/12/2025 a las 8:49pm se envía correo por parte de la jefe de sala de infusión, donde se reporta la cancelación de la paciente en mención. El día de ayer 07/01/2026 se envía orden de preparación donde se relaciona la paciente SANDRA PATRICIA CASTRO TRUJILLO y entendiendo que se tenían los viales del medicamento de la paciente cancelada el 26/12/2025, no se enviaron los viales del medicamento. El día de ayer informa Unidossis que no cuentan con los medicamentos en custodia, ya que, a pesar de la notificación de la cancelación, el medicamento fue preparado, sin embargo, no se recibió ninguna notificación al respecto, tampoco el medicamento fue enviado en físico; teniendo en cuenta que ya pasaron varios días desde el suceso. La estabilidad del medicamento diluido es de 24 horas entre 2-8°C. Esperamos una pronta respuesta sobre este caso y el respectivo plan de mejora, teniendo en cuenta que el día de hoy tuvimos que cancelar a la paciente que estaba programada, lo cual afecta la prestación de nuestros servicios en salud. | J9: DIFERENCIA EN INVENTARIO EN CUSTODIA | K9: SI | L9: MAYOR | M9: PRODUCCIÓN Y DIRECCIÓN TÉCNICA | N9: HENRY GUEVARA BOHORQUEZ | Q9: ABIERTA | S9: ABIERTA | T9: SERVICIO AL CLIENTE | U9: JUAN EDUARDO BOULLY | V9: 5144646 | W9: quimico1.scar@vidamedicalips.com.co | X9: ADJUNTOS | Y9: NO
A10: 1 | B10: 6 | C10: 46031 | D10: ENERO | E10: OCCIDENTE | F10: Clínica San Rafael de Popayán | G10: Clínica San Rafael de Popayán | H10: ONCOLOGÍA | I10: Cordial saludo Por medio del presente realizo reporte defecto de calidad sobre la preparación de la paciente Maritza Baicue Acido zoledronico 4mg, el cual se solicito en dilución de 100mL SSN 0,9%, sin embargo al verificar la preparación recepcionada se evidencia Acido Zoledrónico 4mg en 500mL SSN 0,9%. Realizo reporte con el fin de que se realice la debida verificación del caso, ya que a pesar de que en esta ocasión no afecta la administración del medicamento, puede que este error ocurra en casos futuros donde el volumen de dilución de la preparación de quimioterapia si requiera con exactitud el volumen solicitado. | J10: PRODUCTO NO CONFORME | K10: SI | L10: MAYOR | M10: PRODUCCIÓN Y DIRECCIÓN TÉCNICA | N10: KATY KARINA ORTEGA ACEVEDO | Q10: ABIERTA | S10: ABIERTA | T10: SERVICIO AL CLIENTE | U10: MARIA DEL MAR PERAFAN | V10: 8353810 | W10: quimicofarmaceutico.csrp@stewardcolombia.org | X10: ADJUNTOS | Y10: NO
A11: 1 | B11: 7 | C11: 46031 | D11: ENERO | E11: OCCIDENTE | F11: FUNDACION HOSPITAL SAN CARLOS | G11: FUNDACION HOSPITAL SAN CARLOS BOGOTA | H11: SOLIDOS | I11: Buenas tardes, cordial saludo Envió novedad presentada con la no entrega oportuna del medicamento Itraconazol tableta x 100 mg para el mes de diciembre del 2025, lo que genero que familiar de paciente interpusiera ante la EPS sanitas una queja . | J11: ENTREGA FUERA DEL ACUERDO DE SERVICIO | K11: SI | L11: MAYOR | M11: PRODUCCIÓN Y DIRECCIÓN TÉCNICA | N11: DORIA NARVÁEZ REYES ENRIQUE | P11: 45736 | Q11: CERRADA | S11: ABIERTA | T11: SERVICIO AL CLIENTE | U11: Jimmy Alejandro Calderon Rodriguez QF - farmacovigilancia | V11: 3115059392 | W11: Farmacovigilancia@fhsc.org.co | X11: ADJUNTOS | Y11: NO
A12: 1 | B12: 8 | C12: 46031 | D12: ENERO | E12: MARLY CUNDINAMARCA | F12: CLÍNICA DE MARLY JORGE CAVELIER GAVIRIA | G12: CLINICA DE MARLY CHIA | H12: SOLIDOS | I12: Buen día, Cordial saludo, mediante la presente comunico la novedad presentada el jueves 8 de enero en relación a la orden de producción enviada: Se solicitaron 12 dosis de metilprednisolona 40 mg y en la recepción técnica entregan 2 dosis con etiqueta errónea, la etiqueta tenía lidocaína como medicamento. Muchas gracias, quedo atenta a sus comentarios Cordialmente, | J12: ENTREGA FUERA DEL ACUERDO DE SERVICIO | K12: SI | L12: MAYOR | M12: PRODUCCIÓN Y DIRECCIÓN TÉCNICA | N12: DORIA NARVÁEZ REYES ENRIQUE | Q12: ABIERTA | S12: ABIERTA | T12: SERVICIO AL CLIENTE | U12: VALENTINA MARTÍNEZ MOTTA Química Farmacéutica | V12: 57 1 6532000 Ext. 7331 | W12: quimicoadj.farmacia@marlyjcg.com.co | X12: ADJUNTOS | Y12: NO
A13: 1 | B13: 9 | C13: 46027 | D13: ENERO | E13: CUNDINAMARCA SOLIDOS | F13: FARMART | G13: FARMART | H13: SOLIDOS | I13: Buen día, Se informa que se encontró una novedad durante la recepción técnica del siguiente documento. Se evidenció que el medicamento ALOPURINOL 300MG TABLETA (UNIDOSIS) | ASPEN| ZYLOPRIM presentó un mal etiquetado, ya que el producto llegó con una concentración de 30 mg, lo cual no corresponde a lo solicitado. NOTA: se solicita amablemente urgente la corrección. | J13: ERROR EN ETIQUETA/CODIFICADO | K13: SI | L13: MAYOR | M13: PRODUCCIÓN Y DIRECCIÓN TÉCNICA | N13: DORIA NARVÁEZ REYES ENRIQUE | Q13: ABIERTA | S13: ABIERTA | T13: SERVICIO AL CLIENTE | U13: ANDREA CHANTRE | V13: 3168785821 | W13: auxmedicamentoshuv@farmartips.com | X13: ADJUNTOS | Y13: NO
A14: 1 | B14: 10 | C14: 46027 | D14: ENERO | E14: CUNDINAMARCA SOLIDOS | F14: CLINICA UNIVERSIDAD DE LA SABANA | G14: CLINICA UNIVERSITARIA DE LA SABANA | H14: SOLIDOS | I14: Buenos días. Cordial saludo, El presente correo tiene como finalidad validar la razón por la cual aún no hemos recibido una orden de producción que fue enviada el pasado 23 de diciembre de 2025, teniendo en cuenta que el tiempo establecido para la adecuación de reempaque en dosis unitaria de medicamentos en forma farmacéutica sólida es de aproximadamente 8 días. A la fecha, este plazo se encuentra ampliamente superado, configurándose un incumplimiento en los tiempos acordados. Esta situación ha generado una afectación directa a los pacientes de la clínica, ya que actualmente existen pacientes activos que se encuentran en tratamiento con algunos de los medicamentos incluidos en dicha orden, los cuales han debido ser suspendidos temporalmente debido al retraso presentado. Desde el proceso de Farmacovigilancia, este escenario representa un riesgo para la continuidad terapéutica y la seguridad del paciente, por lo cual resulta prioritario contar con una pronta solución. Agradecemos nos puedan informar de manera inmediata el estado actual de la orden, la causa del incumplimiento y la fecha estimada de entrega, con el fin de tomar las acciones correspondientes y mitigar el impacto generado. No siendo más por el momento, agradezco de antemano la atención prestada y quedo atenta a sus comentarios. | J14: ERROR EN ETIQUETA/CODIFICADO | K14: SI | L14: MAYOR | M14: PRODUCCIÓN Y DIRECCIÓN TÉCNICA | N14: DORIA NARVÁEZ REYES ENRIQUE | Q14: ABIERTA | S14: ABIERTA | T14: SERVICIO AL CLIENTE | U14: SANEHIA NAHOMI MENDOZAQUINTANA | V14: 601 8617777 | W14: claudia.ramos2@clinicaunisabana.edu.co | X14: ADJUNTOS | Y14: NO
A15: 1 | B15: 11 | C15: 46038 | D15: ENERO | E15: OCCIDENTE | F15: CLINICA DESA | G15: CLINICA DESA | H15: NPT | I15: A través de este oficio notifico que, de acuerdo al contrato sostenido entre la clínica DESA S.A.S, clínica Rafel Uribe Uribe y la empresa UNIDOSSIS S.A.S, Nº 206004 relacionado con el suministro de bienes y servicios donde se realiza la elaboración de Nutriciones parenterales-NPT y la preparación de mezclas estériles de medicamentos, notifico que se ha evidenciado incumplimiento en la entrega de las preparaciones que se mencionan con anterioridad relacionado con los siguientes hechos: En la clínica DESA: El día 20 de Diciembre 2025, 8:26am, se realiza solicitud de varias NPT para los días 20 y 21, el día 21 se observa que las NPT llegaron a la clínica DESA después de las 8pm generando inoportunidad en la administración de las nutriciones. Remisionadas con el número 471246 y 470908. En la clínica DESA: El día 27 de Diciembre 2025, hora: 8:50am, se realiza solicitud de varias NPT para los días, 27 y 28, el día 27 y 28 se observa que las NPT llegaron a la clínica DESA después de las 6pm y 7pm generando inoportunidad en la administración de las nutriciones. Remisionadas con el número 472702 y 473006. En la clínica DESA: El día 27 de Diciembre 2025, hora: 8:39am, se realiza solicitud de la mezcla estéril del medicamento Cefazolina 1 g y no se elaboraron para el día que se realizó la solicitud, fueron despachadas un día después. Remisionadas con el número 472911 En la clínica DESA: El día 05 de Enero 2026, 9:44 am, se realiza solicitud de varias NPT para ser entregadas el mismo día, se observa que las NPT llegaron a la clínica DESA a las 6:42pm, generando inoportunidad en la administración de las nutriciones. Remisionadas con el número 474882 En la clínica Nueva Rafael Uribe: El día 05 de Enero 20 realiza solicitud de las mezclas estériles de los medicamentos Cefazolina 2g, Piperacilina y Tazobactam 4.5g, Ampicilina y Sulbactam 3 g, Piperacilina y Tazobactam 13.5g y no fueron preparadas. Desde la dirección técnica del servicio farmacéutico de la clínica DESA y como interventor es muy importante hacer seguimiento al cumplimiento del contrato, luego de tener estas observaciones con respecto a las inoportunidades que se vienen presentado con la empresa UNIDOSSIS S.A.S, yo, como veedor del cumplimiento, notifico para su conocimiento, información que será trasmitida al área jurídica | J15: ENTREGA FUERA DEL ACUERDO DE SERVICIO | K15: SI | L15: MAYOR | M15: PRODUCCIÓN Y DIRECCIÓN TÉCNICA | N15: ANGELA MARCELA PARRA ESPITIA | Q15: ABIERTA | S15: ABIERTA | T15: SERVICIO AL CLIENTE | U15: Yeison Jacob Moreno Murillo Químico Farmacéutico. Director técnico | V15: Tel.: 3814161 Ext. 102 - 117 | W15: yeison.moreno@clinicadesa.com.co | X15: ADJUNTOS | Y15: NO
A16: 1 | B16: 12 | C16: 46041 | D16: ENERO | E16: CUNDINAMARCA | F16: HOSPITAL UNIVERSITARIO SAN IGNACIO | G16: HOSPITAL UNIVERSITARIO SAN IGNACIO | H16: ESTERILES | I16: Buenas tardes equipo Unidossis, reciban un cordial saludo, Confirmo el recibo de la respuesta a los retrasos presentados en el último trimestre del 2025, sin embargo, para dar cierre efectivo de las solicitudes del 2025 aún tenemos pendiente los siguientes casos: FECHA RESPONSABLE DESCRIPCION 14/10/2025 YURI ECHEVERRI DU Heparia con pivote roto (pendiente respuesta con el reporte al proeedor) 7/12/2025 ERIKA ROMERO Du piperacilina con las etiquetas cruzadas, no corresponde el volumen de la jeringa con el declarado en la etiqueta (pendiente respuesta con acciones de mejora) 15/12/2025 YURI ECHEVERRI OP de 50 DU de succinilcolina, llegan 49 (pendiente respuesta con acciones de mejora y emisión de nota crédito por la unidad faltante) 26/12/2025 YURI ECHEVERRI OP de 50 DU de succinilcolina, programada para entrega el 24/12/2025, llega el 25/12/2025 y solo llegan 49 unidades (pendiente respuesta con acciones de mejora y emisión de nota crédito por la unidad faltante) Solicitamos amablemente la colaboración con la revisión de los fallos de calidad. | J16: ENTREGA FUERA DEL ACUERDO DE SERVICIO | K16: SI | L16: MAYOR | M16: PRODUCCIÓN Y DIRECCIÓN TÉCNICA | N16: MARTIN DURANGO | P16: YA SE ENTREGARON TODAS LAS RESPUESTAS DE 2025 | Q16: CERRADA | S16: ABIERTA | T16: SERVICIO AL CLIENTE | U16: Claudia Tinoco Rairán Química Farmacéutica de Aseguramiento de la Calidad | V16: Teléfono: 57 (1) 5946161 Ext. 1066 | W16: cytinoco@husi.org.co | X16: ADJUNTOS | Y16: NO
A17: 1 | B17: 13 | C17: 46041 | D17: ENERO | E17: OCCIDENTE | F17: EMSSANAR EPS | G17: EMSSANAR EPS | H17: ADMINISTRATIVO | I17: Cordial saludo Se reitera la solicitud, teniendo en cuenta que a la fecha no ha sido posible legalizar los recursos girados bajo modalidad de anticipo que a la fecha ascienden a $4.886.100. Por otra parte, se ha intentado establecer una comunicación telefónica con el propósito de conocer el estado de los recursos a las siguientes líneas telefónicas 601-244-40-02 y 3168788032 sin éxito. Cliente Razón social Nro. docto. cruce Fecha docto cruce Total COP Notas 900281394 UNIDOSSIS S.A.S AN-00055676 30/09/2025 4.886.100,00 ANTC. 55676 PTE. LUCIA CASTRO RC. 1108341703 INFUSION DE ALIMENTACION PARENTERAL - OR En caso de presentarse alguna novedad relacionada con la radicación, se solicita informar por este medio con el fin de programar una mesa de trabajo que permita brindar acompañamiento y capacitación por parte del equipo de radicación, en el proceso de cargue de facturas y soportes a través de la plataforma RISPLINK. En caso de que el servicio no haya sido prestado, se solicita el reintegro de los recursos correspondientes, los cuales deberán ser consignados en la cuenta bancaria adjunta. Agradezco la atención prestada | J17: INCUMPLIMIENTO ACTIVIDADES O COMPROMISOS | K17: SI | L17: MAYOR | M17: PRODUCCIÓN Y DIRECCIÓN TÉCNICA | N17: MANUEL GASCA | O17: 46053 | P17: 46053 | Q17: CERRADA | R17: 31/*01/2026 | S17: CERRADA | T17: SERVICIO AL CLIENTE | U17: STEPHANNY CALPA Legalización Anticipos Salud | V17: 3176990583 | W17: legalizacionanticipossalud@emssanareps.co | X17: ADJUNTOS | Y17: NO
A18: 1 | B18: 14 | C18: 46041 | D18: ENERO | E18: CUNDINAMARCA | F18: SOCIEDAD DE CIRUGIA DE BOGOTA HOSPITAL DE SAN JOSE | G18: HOSPITAL INFANTIL UNIVERSITARIO SAN JOSE | H18: NPT | I18: Asunto: Queja terminación NPT Buenos días. Se adjunta documento de queja con relación al asunto. Sin otro particular, gracias por la atención. Cordial saludo, Juana Vargas Químico Farmacéutico Servicio Farmacéutico Sociedad de Cirugía de Bogotá Hospital de San José 3538000 Ext. 468-422 | J18: PRODUCTO NO CONFORME | K18: SI | L18: MAYOR | M18: PRODUCCIÓN Y DIRECCIÓN TÉCNICA | N18: MARTIN DURANGO | Q18: ABIERTA | S18: ABIERTA | T18: SERVICIO AL CLIENTE | U18: Juana Vargas Químico Farmacéutico | V18: 3538000 Ext. 468-422 | W18: rordenespro20211123@gmail.com | X18: ADJUNTOS | Y18: NO
A19: 1 | B19: 15 | C19: 46041 | D19: ENERO | E19: CUNDINAMARCA | F19: CHRISTUS SINERGIA | G19: CHRISTUS SINERGIA | H19: TODAS | I19: Buen día, Espero se encuentren muy bien. Por medio del presente, me permito radicar una PQR debido al retraso en la entrega de las adecuaciones y ajustes de medicamentos estériles y nutriciones parenterales solicitadas en horas de la mañana del día de hoy. Adjunto a este correo la PQR correspondiente, así como un fragmento del contrato en el cual se establecen los horarios de entrega. De acuerdo con lo allí estipulado, se evidencia un incumplimiento en la prestación del servicio en la fecha mencionada. Agradecemos su pronta respuesta y las acciones que consideren pertinentes, con el fin de fortalecer los procesos y garantizar el bienestar y la seguridad de los pacientes. Muchas gracias. | J19: ENTREGA FUERA DEL ACUERDO DE SERVICIO | K19: SI | L19: MAYOR | M19: PRODUCCIÓN Y DIRECCIÓN TÉCNICA | N19: ANGELA MARCELA PARRA ESPITIA | Q19: ABIERTA | S19: ABIERTA | T19: SERVICIO AL CLIENTE | U19: YESICA ALEJANDRA GOEZ | V19: N/R | W19: quimicofarmaceutico2.cpr@christus.co | X19: ADJUNTOS | Y19: NO
A20: 1 | B20: 16 | C20: 46042 | D20: ENERO | E20: SANTANDER | F20: SIES SALUD | G20: SIES SALUD | H20: ONCOLOGÍA | I20: Buenos días, Señores Unidosis: Por medio de la presente queremos informar el error identificado en las cédulas de todos los pacientes con preparaciones de oncología correspondientes al día 05 de enero de 2026. Si bien el incidente no generó consecuencias graves, sí representó un riesgo potencial para la seguridad de los pacientes, motivo por el cual consideramos importante revisarlo con ustedes. Con el fin de fortalecer los procesos y garantizar la confiabilidad de la información, solicitamos nos compartan: Las acciones de mejora que se implementarán para evitar que este tipo de situaciones se repitan. Los ajustes o controles adicionales que consideren pertinentes para reforzar la seguridad en la preparación y validación de datos de los pacientes. Agradecemos su atención y el compromiso con la mejora continua, así como la disposición para trabajar conjuntamente en la prevención de futuros inconvenientes. Atentamente, | J20: PRODUCTO NO CONFORME | K20: SI | L20: MAYOR | M20: PRODUCCIÓN Y DIRECCIÓN TÉCNICA | N20: IVAN PEREIRA | O20: 46048 | P20: 46048 | Q20: CERRADA | S20: ABIERTA | T20: SERVICIO AL CLIENTE | U20: David José Ortega Redondo Profesional Asistencial Químico Farmacéutico | V20: (7) 6970001 - 319 2729798 | W20: dortegar@siessalud.com.co | X20: ADJUNTOS | Y20: NO
A21: 1 | B21: 17 | C21: 46042 | D21: ENERO | E21: SANTANDER | F21: CLINICA MATERNO INFANTIL DE SAN LUIS | G21: CLINICA SAN LUIS | H21: ONCOLOGÍA | I21: Se recibe el día 22 de diciembre en turno de la noche cafeína en unidosis solicitada 20 mg. Llega medicamento con etiqueta marcada de 20 mg, pero se observa solo 0.1 CC. la dosis corresponde a 1 CC. # LOTE 07213R53786 Revisando la orden de produccion enviada a unidosis el día 22 de diciembre a las 15;57:34, la dosis es de 20 MG de cafeina a nombre de NICOLAS CAMPO LOZANO con registro 3053764 Favor enviar respuesta de lo acontecido Cordial saludo | J21: ERROR EN ETIQUETA/CODIFICADO | K21: SI | L21: MAYOR | M21: PRODUCCIÓN Y DIRECCIÓN TÉCNICA | N21: IVAN PEREIRA | O21: 46048 | P21: 206/21/2026 | Q21: CERRADA | S21: ABIERTA | T21: SERVICIO AL CLIENTE | U21: N/R | V21: N/R | W21: quimico.farmaceutico@clinicasanluis.com.co> | X21: ADJUNTOS | Y21: NO
A22: 1 | B22: 18 | C22: 46043 | D22: ENERO | E22: COSTA | F22: CLINICA INTERNACIONAL LA MISERICORDIA. OINSAMED | G22: CLINICA INTERNACIONAL LA MISERICORDIA OINSAMED | H22: ESTERILES | I22: Buenas tardes La presente es para informar que en el dia de hoy llegaron de parte de ustedes 3 unidosis de Piperacilina+tazobactam de 4,5 g sin el empaque externo correspondiente al paciente Jose Gomez Altamar, debido a que no cumplió con la recepción técnica se devuelve las preparaciones. Adjunto foto | J22: ERROR DE EMPAQUE | K22: SI | L22: MAYOR | M22: PRODUCCIÓN Y DIRECCIÓN TÉCNICA | N22: ESTEFANIA MARTINEZ MARTINEZ | O22: 46043 | P22: 46043 | Q22: CERRADA | S22: ABIERTA | T22: SERVICIO AL CLIENTE | U22: JANELLY OTERO MEDRANO Químico farmacéutico | V22: 3112640 ext 1010 | W22: produccioncm@lmci.com.co | X22: ADJUNTOS | Y22: NO
A23: 1 | B23: 19 | C23: 46044 | D23: ENERO | E23: CUNDINAMARCA SOLIDOS | F23: HOSPITAL UNIVERSITARIO SAN IGNACIO | G23: HOSPITAL UNIVERSITARIO SAN IGNACIO | H23: SOLIDOS | I23: Buenas tardes Francisco, te remito las fotos de la novedad de reempaque detectada el día de hoy. Cordialmente, | J23: ERROR DE RE EMPAQUE | K23: SI | L23: MAYOR | M23: PRODUCCIÓN Y DIRECCIÓN TÉCNICA | N23: DORIA NARVÁEZ REYES ENRIQUE | Q23: ABIERTA | S23: ABIERTA | T23: SERVICIO AL CLIENTE | U23: Viviana Andrea Pinzón García QF Esp.Jefe de Servicio Farmacéutico | V23: Teléfono: 57 (1) 5946161 Ext. 1045 | W23: vapinzon@husi.org.co | X23: ADJUNTOS | Y23: NO
A24: 1 | B24: 20 | C24: 46045 | D24: ENERO | E24: CUNDINAMARCA | F24: HOSPITAL UNIVERSITARIO SAN IGNACIO | G24: HOSPITAL UNIVERSITARIO SAN IGNACIO | H24: ESTERILES | I24: Cordial saludo Unidossis, El presente correo es para reportar las siguientes novedades/inconvenientes respecto a la entrega de la OP de Heparinas. Las DUs de Heparina debían llegar para el día (20/01/2026), sin embargo, llegaron hasta el día (22/01/2026) en horas de la tarde. Esto conlleva a la entrega NO oportuna de los medicamentos a los pacientes. Dicho lo anterior se solicita: Acciones de mejora a implementar para minimizar este tipo de inconvenientes. Reunión con el fin de esclarecer nuevamente los acuerdos de servicio, para que resulten favorables para ambas partes. Quedo atento a cualquier inquietud. Cordialmente, | J24: ENTREGA FUERA DEL ACUERDO DE SERVICIO | K24: SI | L24: MAYOR | M24: PRODUCCIÓN Y DIRECCIÓN TÉCNICA | N24: MARTIN DURANGO | O24: 46094 | P24: 46094 | Q24: CERRADA | S24: ABIERTA | T24: SERVICIO AL CLIENTE | U24: Yuri Alberto Echeverri Pineda Químico Farmacéutico Asistencial | V24: Teléfono: (601) 5946161 Ext. 3007 | W24: yaecheverri@husi.org.co | X24: ADJUNTOS | Y24: NO
A25: 1 | B25: 21 | C25: 46048 | D25: ENERO | E25: OCCIDENTE | F25: FUND CLINICA INFANTIL CLUB NOEL | G25: FUND CLINICA INFANTIL CLUB NOEL | H25: ONCOLOGÍA | I25: Por medio del presente me permito reportar una inconformidad relacionada con la llegada de las quimioterapias y PME del sábado 24 de enero de 2026. Los medicamentos llegaron a la clínica a las 6:20 p.m. para su entrega. Cabe resaltar que el correo con la orden de producción de las quimioterapias se envió a Unidossis a las 8:06 a.m. No obstante, las preparaciones llegaron a las 6:20 p.m., a pesar de que inicialmente la química Samantha había informado que estarían llegan a la clínica a las 2:00 p.m. A las 3:00 p.m., la química Samantha se comunicó con la regente Karen Carabalí para preguntar si era posible realizar la entrega a las 5:00 p.m., a lo cual se le indicó que no, dado que los pacientes ya debían estar recibiendo su tratamiento. Posteriormente, a las 5:00 p.m. Se realizó otra llamada, en la cual la química Samantha informó que las preparaciones estaban próximas a llegar. Sin embargo, estas solo fueron entregadas a las 6:20 p.m. Adicionalmente, se presentó un error en la preparación para el paciente Janer Arley Gómez Flores, a quien se le envió preparar citarabina 500 mg (cantidad 2) en dosis de 225 mg en un volumen de 100 ml. Sin embargo, al momento de la entrega en la clínica se recibió únicamente 1 preparación, razón por la cual el domingo se envió a preparar el faltante para que el paciente pudiera completar su tratamiento. adjunto imagen de la orden de preparación del dia sabado 24/01 /2026 donde se evidencia que se envió a preparar cantidad 2 citarabina 500mg Este retraso ocasionó afectaciones en el tratamiento de 8 pacientes con tratamiento de quimioterapia, así como en los pacientes de las PME, considerando que algunos tenían dosis programadas a las 6:00 p.m. | J25: ENTREGA FUERA DEL ACUERDO DE SERVICIO | K25: SI | L25: MAYOR | M25: PRODUCCIÓN Y DIRECCIÓN TÉCNICA | N25: ANGELA MARCELA PARRA ESPITIA | Q25: ABIERTA | S25: ABIERTA | T25: SERVICIO AL CLIENTE | U25: Karen Carabali Abonia Regente de Farmacia | V25: Tel: 602 485 44 04 Ext.: 1128 | W25: central.mezclas@fciclubnoel.com | X25: ADJUNTOS | Y25: NO
A26: 1 | B26: 22 | C26: 46048 | D26: ENERO | E26: CUNDINAMARCA | F26: HOSPITAL UNIVERSITARIO SAN IGNACIO | G26: HOSPITAL UNIVERSITARIO SAN IGNACIO | H26: ESTERILES | I26: Cordial saludo El presente con el fin de reportar queja en cuanto al retraso en entrega de las dosis unitarias de estériles del día 23 de enero las cuales se recibieron a las 18:39 (horario pactado 17:00). Agradezco la atención prestada y quedo atenta a comentarios. | J26: ENTREGA FUERA DEL ACUERDO DE SERVICIO | K26: SI | L26: MAYOR | M26: PRODUCCIÓN Y DIRECCIÓN TÉCNICA | N26: MARTIN DURANGO | O26: 46094 | P26: 46094 | Q26: CERRADA | S26: ABIERTA | T26: SERVICIO AL CLIENTE | U26: Luisa Ovalle Químico Farmacéutico Asistencial | V26: Teléfono: (601) 5946161 Ext. 3007 | W26: luovalle@husi.org.co | X26: ADJUNTOS | Y26: NO
A27: 1 | B27: 23 | C27: 46049 | D27: ENERO | E27: CUNDINAMARCA | F27: CLINICA UNIVERSIDAD DE LA SABANA | G27: CLINICA UNIVERSITARIA DE LA SABANA | H27: DOSIS ANTICIPADA | I27: Buen día, Mediante el presente reporto, el día sábado recibimos la orden de producción 479522 correspondiente a 100 JP de hidromorfona lote: RC2664494, y al realizar la inspección de calidad, se evidencia una jeringa con particulas en la parte superior y color oxido. Solicitamos una revisión de lo ocurrido. Asimismo, agradecemos nos informen las medidas correctivas que se implementarán para evitar que estos errores se repitan. Además, requerimos que se nos indique cómo se realizará la reposición de la unidad afectada. | J27: PRODUCTO NO CONFORME | K27: SI | L27: MAYOR | M27: PRODUCCIÓN Y DIRECCIÓN TÉCNICA | N27: MARTIN DURANGO | Q27: ABIERTA | S27: ABIERTA | T27: SERVICIO AL CLIENTE | U27: MARIA ALEJANDRA CAMPOS ACOSTA | V27: 8617777 | W27: maria.campos2@clinicaunisabana.edu.co | X27: ADJUNTOS | Y27: NO
A28: 1 | B28: 24 | C28: 46049 | D28: ENERO | E28: CUNDINAMARCA | F28: CLINICA ZENTRIA LA MILAGROSA SAS | G28: CLINICA ZENTRIA LA MILAGROSA SAS | H28: ONCOLOGÍA | I28: Buen día, cordial saludo. El día de ayer se mandó la solicitud de preparación de medicamento Oncológico, a las 2:59pm (adjunto evidencia). A las 9 de la mañana de hoy se recibe la llamada de que no fue preparado porque el correo fue recibido muy tarde; a pesar de que expresaron que se podía mandar el día de hoy lo antes posible, no se puede recibir en horas de la tarde debido a que la programación de los pacientes y la enfermera jefe ya se encontraba establecida. Ante estas eventualidades agradezco se genere un plan de acción. Recomendamos contestar el recibido de los correos, así mismo notificar si no se va a poder preparar sea porque se mandó tarde o porque se recibió tarde, esto para poder coordinar con el servicio de Quimioterapia y con los pacientes. Quedo atenta, gracias. | J28: ENTREGA FUERA DEL ACUERDO DE SERVICIO | K28: SI | L28: MAYOR | M28: PRODUCCIÓN Y DIRECCIÓN TÉCNICA | N28: MARTINEZ GRANADOS MARIA VICTORIA | Q28: ABIERTA | S28: ABIERTA | T28: SERVICIO AL CLIENTE | U28: ANDREA ARDILA PINEDA | V28: 4351847 | W28: andrea.ardila@zentria.com.co | X28: ADJUNTOS | Y28: NO
A29: 1 | B29: 25 | C29: 46049 | D29: ENERO | E29: CUNDINAMARCA | F29: SOCIEDAD DE CIRUGIA DE BOGOTA HOSPITAL DE SAN JOSE | G29: HOSPITAL DE SAN JOSE | H29: NPT | I29: "Buen día, Por medio de la presente es para informar que el día 26/01/2026 se recibió una nutrición sin el peso correspondiente de la paciente H/HAREN ESTEFANIA JIMENEZ SILVA, es importante resaltar que las nutriciones deben venir con el peso ya que es nuestra forma de darle seguimiento y validar que se encuentre en los rangos de aceptación. Se realizó la verificación de los volumenes de la nutrición y correspondian, sin embargo, es necesario que todas las nutriciones vengan con el peso. Agradecemos su colaboración para que esta situción no se vuelva a presentar. Se adjunta evidencia fotografica. " | J29: PRODUCTO NO CONFORME | K29: SI | L29: MAYOR | M29: PRODUCCIÓN Y DIRECCIÓN TÉCNICA | N29: MARTIN DURANGO | Q29: ABIERTA | S29: ABIERTA | T29: SERVICIO AL CLIENTE | U29: Juana Camila Vargas Yasser - Química Farmacéutica | V29: 3538000 Ext. 468 | W29: rordenespro20211123@gmail.com | X29: ADJUNTOS | Y29: NO
A30: 1 | B30: 26 | C30: 46050 | D30: ENERO | E30: COSTA | F30: CLINICA MAICA NUESTRA | G30: CLINICA MAICAO NUESTRA | H30: NPT | I30: Cordial saludo, Por medio del presente, nos permitimos solicitar muy respetuosamente que cualquier inconveniente relacionado con la producción y/o transportación de las Nutriciones Parenterales Totales (NPT) sea notificado de manera inmediata, en la medida de lo posible. Lo anterior se fundamenta en que nuestra Unidad de Cuidados Intensivos Neonatal cuenta actualmente con pacientes hospitalizados a la espera de este soporte nutricional, el cual resulta crítico para su manejo clínico. Si bien comprendemos que UNIDOSSIS se encuentra ubicado en la ciudad de Barranquilla y nuestra institución en Maicao, La Guajira, y que la distancia representa un factor relevante en los tiempos de entrega, se hace indispensable contar con una comunicación oportuna que nos permita tomar medidas clínicas y administrativas preventivas. De manera puntual, informamos que actualmente contamos con tres pacientes en espera de la NPT, correspondiente a la orden de despacho No. 4456675, la cual fue recibida en nuestra institución a las 10:35 a.m. del día de hoy, situación que genera un impacto directo en la continuidad del tratamiento de los pacientes neonatales. Adicionalmente, agradecemos nos sea suministrado un medio que permita realizar la trazabilidad completa del pedido, de tal forma que podamos conocer de manera oportuna el estado del mismo (producción, despacho y transporte) y así tomar las medidas asistenciales necesarias para garantizar la seguridad del paciente y la continuidad del tratamiento. Agradecemos de antemano su colaboración y disposición para fortalecer los canales de comunicación. Quedamos atentos a cualquier información adicional. | J30: ENTREGA FUERA DEL ACUERDO DE SERVICIO | K30: SI | L30: MAYOR | M30: PRODUCCIÓN Y DIRECCIÓN TÉCNICA | N30: MARTINEZ GRANADOS MARIA VICTORIA | Q30: ABIERTA | S30: ABIERTA | T30: SERVICIO AL CLIENTE | U30: VALENTINA MENDOZA GALEANO Directora Técnica del Servicio Farmacéutico ALDAIR DE LA CRUZ PERTUZ Químico Farmacéutico Asistencial | V30: ☎️ Teléfono: (605) 7256500 Ext. 1005 | W30: farmacia@clinicamaicao.com | X30: ADJUNTOS | Y30: NO
A31: 1 | B31: 27 | C31: 46050 | D31: ENERO | E31: CUNDINAMARCA | F31: HOSPITAL UNIVERSITARIO SAN IGNACIO | G31: HOSPITAL UNIVERSITARIO SAN IGNACIO | H31: ESTERILES | I31: Cordial saludo El presente con el fin de reportar queja en cuanto al retraso en entrega de las dosis unitarias de estériles del día 27 de enero las cuales se recibieron a las 18:27 (horario pactado 17:00). Adjunto envío documento. Agradezco la atención prestada y quedo atenta a comentarios. Cordialmente | J31: ENTREGA FUERA DEL ACUERDO DE SERVICIO | K31: SI | L31: MAYOR | M31: PRODUCCIÓN Y DIRECCIÓN TÉCNICA | N31: MARTIN DURANGO | Q31: ABIERTA | S31: ABIERTA | T31: SERVICIO AL CLIENTE | U31: Luisa Ovalle Químico Farmacéutico Asistencial | V31: Teléfono: (601) 5946161 Ext. 3007 | W31: luovalle@husi.org.co | X31: ADJUNTOS | Y31: NO
A32: 1 | B32: 28 | C32: 46050 | D32: ENERO | E32: CUNDINAMARCA | F32: VANTIVE S.A.S. | G32: VANTIVE | H32: DOSIS ANTICIPADA | I32: Buen día Cordial saludo Por medio de la presente solicito la colaboración para realizar recolección y cambio en físico de 50 unidosis de HEPARINA SODICA 3000UI/5ML con la REMISION 476375 ya que se evidencia que la solicitud fue emitida y grabada por HEPARINA SODICA 5000UI . | J32: ERROR EN ETIQUETA/CODIFICADO | K32: SI | L32: MAYOR | M32: PRODUCCIÓN Y DIRECCIÓN TÉCNICA | N32: MARTIN DURANGO | Q32: ABIERTA | S32: ABIERTA | T32: SERVICIO AL CLIENTE | U32: Carlos Alberto Vergara Vergara Sr Analista de Inventarios RCS – Procurement | V32: Celular: 3154947751 | W32: Email: carlos.vergara@vantive.com | X32: ADJUNTOS | Y32: NO
A33: 1 | B33: 29 | C33: 46051 | D33: ENERO | E33: CUNDINAMARCA | F33: CLINICA UNIVERSIDAD DE LA SABANA | G33: CLINICA UNIVERSITARIA DE LA SABANA | H33: DOSIS ANTICIPADA | I33: Buen día, Mediante el presente reporto, el día de ayer miercoles 28/01/2026 recibimos la orden de producción 480543 correspondiente a 100 JP de hidromorfona lote: RC2675942, y al realizar la inspección de calidad, se evidencia una jeringa sin etiqueta interna y una sin identificación ni interna ni externa. Solicitamos una revisión de lo ocurrido. Asimismo, agradecemos nos informen las medidas correctivas que se implementarán para evitar que estos errores se repitan. Además, requerimos que se nos indique cómo se realizará la reposición de la unidad afectada. | J33: PRODUCTO NO CONFORME | K33: SI | L33: MAYOR | M33: PRODUCCIÓN Y DIRECCIÓN TÉCNICA | N33: MARTIN DURANGO | Q33: ABIERTA | S33: ABIERTA | T33: SERVICIO AL CLIENTE | U33: MARIA ALEJANDRA CAMPOS ACOSTA | V33: 8617777 | W33: maria.campos2@clinicaunisabana.edu.co | X33: ADJUNTOS | Y33: NO
A34: 1 | B34: 30 | C34: 46051 | D34: ENERO | E34: CUNDINAMARCA | F34: FUNDACION ABOOD SHAIO | G34: FUND SHAIO | H34: DOSIS ANTICIPADA | I34: Los medicamentos se enviarán esta misma tarde. Tener en cuenta que la Ketamina es un medicamento de control especial, por lo que se requiere reposición lo más pronto posible. Del mismo modo, se solicita el reempaque de la tableteria con la información legible (en el reempaque también van medicamentos controlados como Hidromorfona 2,5 mg tableta). ASUNTO: Reclamo técnico 20-26 KETAMINA 10MG/ML JERINGA PRELLENA X 5ML LOTE RC2645962 "Jeringa la cual se encuentra dentro de la bolsa sellada y al abrir la bolsa se encuentra jeringa solo con 3CC de ketamina y protector de punta de jeringa roto" ASUNTO: Reclamo técnico 21-26 JP HEPARINA 5000 UNDX 1ML "Se decide administrar heparina, se pincha el paciente y se visualiza que no hay medicamento; vale la pena resaltar que estaba sellada la bolsa de Unidossis." | J34: PRODUCTO NO CONFORME | K34: SI | L34: MAYOR | M34: PRODUCCIÓN Y DIRECCIÓN TÉCNICA | N34: MARTIN DURANGO | Q34: ABIERTA | S34: ABIERTA | T34: SERVICIO AL CLIENTE | U34: Oscar Alfonso Vargas Bautista Químico(a) Farmacéutico(a) | V34: PBX (601) 593 8210 | W34: alfonso.vargas@shaio.org | X34: ADJUNTOS | Y34: NO
A35: 1 | B35: 31 | C35: 46051 | D35: ENERO | E35: CUNDINAMARCA | F35: FUNDACION ABOOD SHAIO | G35: FUND SHAIO | H35: SOLIDOS | I35: ASUNTO: Reclamo técnico 22-26 TraZODona 50 mg CAP "No se evidencia medicamento dentro del reempaque ni información del medicamento; se saca del paquete de la bolsa de trazodona, se evidencia reempaque sellado." ASUNTO: Reclamo técnico 23-26 CALCITRIOL 0,25MCG TAB “Se evidencian 2 unidades de Calcitriol en 1 mismo reempaque" ASUNTO: Reclamo técnico 24-26 ELTROMBOPAG X 50MG TABLETA REC "Información del medicamento ilegible" ASUNTO: Reclamo técnico 34-26 HIDROMORFONA 2,5MG TAB "información no legible del reempaque" ASUNTO: Reclamo técnico 430-25 ACETAMINOFEN 500 MG TAB "Información ilegible, código de barras borrado" | J35: PRODUCTO NO CONFORME | K35: SI | L35: MAYOR | M35: PRODUCCIÓN Y DIRECCIÓN TÉCNICA | N35: MARTIN DURANGO | Q35: ABIERTA | S35: ABIERTA | T35: SERVICIO AL CLIENTE | U35: Oscar Alfonso Vargas Bautista Químico(a) Farmacéutico(a) | V35: PBX (601) 593 8210 | W35: alfonso.vargas@shaio.org | X35: ADJUNTOS | Y35: NO
A36: 1 | B36: 32 | C36: 46051 | D36: ENERO | E36: COSTA | F36: CLINICA INTERNACIONAL LA MISERICORDIA. OINSAMED | G36: CLINICA INTERNACIONAL LA MISERICORDIA OINSAMED | H36: SOLIDOS | I36: ASUNTO: MEDICAMENTO SIN EMPAQUE EXTERNO Reciba un cordial saludo. Por medio de la presente nos dirigimos a ustedes con el fin de dar respuesta a la queja interpuesta, con número de radicado 150126-1 MEDICAMENTO SIN EMPAQUE EXTERNO, no sin antes agradecerles por la realización de estos reportes ya que contribuye con nuestros procesos de mejora continua, y nos impulsa a seguir trabajando para mantener la satisfacción del cliente. | J36: PRODUCTO NO CONFORME | K36: SI | L36: MAYOR | M36: PRODUCCIÓN Y DIRECCIÓN TÉCNICA | N36: MARTIN DURANGO | Q36: ABIERTA | S36: ABIERTA | T36: SERVICIO AL CLIENTE | U36: ISIS MADALÉN MONTENEGRO QUINTERO Coordinador Logístico | V36: Fijo: 3112640 Ext: 1011 Móvil: 350-6007491 | W36: coor.farmacia@lmci.com.co | X36: ADJUNTOS | Y36: NO
A37: 1 | B37: 33 | C37: 46051 | D37: ENERO | E37: COSTA | F37: CLINICA BAHIA | G37: CLINICA BAHIA | H37: SOLIDOS | I37: Buenos días, Saludos cordiales. De acuerdo con lo conversado vía telefónica, me permito informar el producto no conforme detectado durante el proceso de recepción Tecnica de los preparados del día 28/01/2026, el cual 1 unidad presentó salida de líquido (fuga), motivo por el cual no pudo ser dispensado al servicio de UCI, lo cual nos genera un faltante en el invetario del servicio farmaceutico. Detalle del producto: Medicamento: Vancomicina Concentración / Volumen: 1 g / 250 mL Lote interno: RB2680179 Cantidad: 1 unidad Se adjunta formato institucional de medicamentos averiados y registro fotográfico de la novedad. Agradecemos tener en cuenta que, al momento de la facturación del día 28/01/2026, no incluir esta unidosis y se solicita la reposición en inventario de las 2 ampollas correspondientes a la preparación. | J37: PRODUCTO NO CONFORME | K37: SI | L37: MAYOR | M37: PRODUCCIÓN Y DIRECCIÓN TÉCNICA | N37: MARTINEZ GRANADOS MARIA VICTORIA | Q37: ABIERTA | S37: ABIERTA | T37: SERVICIO AL CLIENTE | U37: Brenda Morales Tinoco Quimico Farmaceutico. | V37: N/R | W37: controlgasesmedicinales@clinicabahia.com | X37: ADJUNTOS | Y37: NO
A38: 1 | B38: 34 | C38: 46051 | D38: ENERO | E38: CUNDINAMARCA | F38: FUNDACION HOSPITAL SAN CARLOS | G38: FUNDACION HOSPITAL SAN CARLOS BOGOTA | H38: SOLIDOS | I38: Buenas tardes, cordial saludo Me permito informar que actualmente se ha venido identificando novedades con los medicamentos que llegan reempacados a la institución fundación hospital san Carlos. Las novedades están relacionadas principalmente con el empaque, como se muestra en las imágenes adjuntas // Se están entregando medicamentos que no cuentan con la ranura de separación, generando que al momento de la dispensación se rompa todo el empaque lo cual lleva a que el medicamento quede suelto y sin ningún tipo de identificación. Medicamento sin ranura para la separación Esta novedad técnica esta generando que se realicen reprocesos [ dado que se tiene que utilizar una persona de manera diaria para que realice el respectivo corte o separación | J38: PRODUCTO NO CONFORME | K38: SI | L38: MAYOR | M38: PRODUCCIÓN Y DIRECCIÓN TÉCNICA | N38: DORIA NARVÁEZ REYES ENRIQUE | P38: 46101 | Q38: CERRADA | S38: ABIERTA | T38: SERVICIO AL CLIENTE | U38: Jimmy Alejandro Calderon Rodriguez QF - FHSC | V38: N/R | W38: farmacovigilancia@fhsc.org.co | X38: ADJUNTOS | Y38: NO
A39: 1 | B39: 35 | C39: 46051 | D39: ENERO | E39: CUNDINAMARCA | F39: FARMART | G39: FARMART | H39: SOLIDOS | I39: Buen día, Informo las novedades encontradas mientras se realizaba el proceso de recepción de unidosis: Código Interno Descripción Lote Fecha Vencimiento Stock Observacion 39598 GABAPENTIN 300MG TABLETA (UNIDOSIS) | LEGRAND | KAPTIN B02505 2027-07-30 1 averia 43507 QUETIAPINA 25MG TABLETA (UNIDOSIS) | HETERO LABS LIMITED| TIQUEPIN| TQD241102 2027-10-30 10 sobrante 44074 SILDENAFIL 50MG TABLETA (UNIDOSIS) | GENFAR | F01689E 2027-07-30 212 error en lote 50265 ACETAMINOFEN + CODEINA 325MG + 30MG TABLETA (UNIDOSIS) | NOVAMED | APRIX 2511004637 2027-11-30 16 pendiente por entrega El medicamento que se indica como sobrante se evidencio que el paquete indicaba 50 unidades pero fisicamente llegaron 60 unidades. En el caso del medicamento ACETAMINOFEN + CODEINA 325MG + 30MG TABLETA (UNIDOSIS) | NOVAMED | APRIX, se enviaron a reempaque un total de 200 unidades. No obstante, al momento de realizar el proceso de recepción de unidosis y la revisión del documento de reempaque, se evidencia que fueron remisionadas y entregadas únicamente 184 unidades, presentándose un faltante de 16 unidades, las cuales se encuentran pendientes de envío por parte de ustedes. Adicionalmente, se solicita su amable colaboración respecto a la unidad de empaque, dado que se evidenció que algunos paquetes indicaban contener 50 unidades, información que no correspondía con el contenido real. | J39: PRODUCTO NO CONFORME | K39: SI | L39: MAYOR | M39: PRODUCCIÓN Y DIRECCIÓN TÉCNICA | N39: MARTINEZ GRANADOS MARIA VICTORIA | Q39: ABIERTA | S39: ABIERTA | T39: SERVICIO AL CLIENTE | U39: ANDREA CHANTRE AUX FARMACIA | V39: 3168785821 | W39: auxmedicamentoshuv@farmartips.com | X39: ADJUNTOS | Y39: NO
A40: 1 | B40: 36 | C40: 46051 | D40: ENERO | E40: CUNDINAMARCA | F40: CHRISTUS SINERGIA | G40: CHRISTUS SINERGIA | H40: SOLIDOS | I40: Buen día, Espero se encuentren muy bien. El día de ayer, 02/02/2026, se evidenció un retraso aproximado de una hora, el cual no fue informado oportunamente, tal como se establece en el contrato. Debido a esta falta de notificación, no fue posible alertar a los diferentes servicios sobre la tardanza en la entrega de las adecuaciones. Es importante dar estricto cumplimiento a los horarios de llegada, ya que este tipo de retrasos puede generar afectaciones en la administración de medicamentos y comprometer la seguridad del paciente. Adicionalmente, durante la mañana se realizó la solicitud de algunas adecuaciones requeridas por pacientes, las cuales no fueron entregadas dentro de las adecuaciones recepcionadas el día de ayer. Agradecemos se tomen las medidas necesarias para evitar la recurrencia de estas situaciones y se dé cumplimiento a lo establecido. Quedamos atentos a sus comentarios. | J40: PRODUCTO NO CONFORME | K40: SI | L40: MAYOR | M40: PRODUCCIÓN Y DIRECCIÓN TÉCNICA | N40: MARTINEZ GRANADOS MARIA VICTORIA | Q40: ABIERTA | S40: ABIERTA | T40: SERVICIO AL CLIENTE | U40: YESICA ALEJANDRA GOEZ PUENTES | V40: N/R | W40: quimicofarmaceutico2.cpr@christus.co | X40: ADJUNTOS | Y40: NO
...

Sheet OTROS
A1: REGIONAL | B1: LINEA | C1: CALSIFICACION | D1: TIPO DE SOLICITUD | E1: PROCESO | F1: TIPIFICACION | G1: MEDIO EN QUE ENVIA LA QUEJA | H1: PROCESOS RELACIONADO
A2: ANTIOQUIA | B2: ADMINISTRATIVO | C2: CRITICO | D2: FELICITACION | E2: GERENCIA GENERAL | F2: PRODUCTO NO CONFORME | G2: CARTA | H2: SERVICIO
A3: COSTA | B3: DOSIS ANTICIPADA | C3: MAYOR | D3: PREGUNTA | E3: PRODUCCIÓN Y DIRECCIÓN TÉCNICA | F3: NO CONFORMIDAD ENTRE LO SOLICITADO Y LO ENTREGADO | G3: IMAIL | H3: TECNICA
A4: CUNDINAMARCA | B4: ESTERILES | C4: MENOR | D4: QUEJA | E4: COMERCIAL | F4: REPORTE DE FARMACOVIGILANCIA | G4: OTRO
A5: EJE CAFETERO | B5: MAGISTRAL NO ESTERILES | C5: IMPRESINDIBLE | D5: RECLAMO | E5: OPERACIONES Y LOGÍSTICA | F5: DIFERENCIA EN INVENTARIO EN CUSTODIA | G5: PERSONAL
A6: LLANOS | B6: NPT | C6: IMPORTANTE | D6: SUGERENCIA | E6: ADMINISTRATIVA Y FINANCIERA | F6: ENTREGA FUERA DEL ACUERDO DE SERVICIO | G6: TELEFONO
A7: MARLY CUNDINAMARCA | B7: ONCOLOGÍA | C7: NORMAL | E7: TALENTO HUMANO | F7: ERROR ALMACENAMIENTO/TRANSPORTE DE MEDICAMENTOS E INSUMOS | G7: WEB
A8: OCCIDENTE | B8: SOLIDOS | E8: SEGURIDAD Y SALUD EN EL TRABAJO | F8: ERROR DE INTERPRETACIÓN
A9: SANTANDER | B9: TODAS | F9: ERROR DE EMBALAJE
A10: CUNDINAMARCA SOLIDOS | B10: LOGISTICA | E10: ASEGURAMIENTO DE CALIDAD | F10: ERROR DE EMPAQUE
A11: CUNDINAMARCA MAGISTRALES | B11: LOGISTICA (BLITZ) | F11: ERROR DE RE EMPAQUE
A12: BLITZ CELTA | F12: ERROR EN ETIQUETA/CODIFICADO
A13: BLITZ TOCANCIPA | F13: ERROR EN DESPACHO
A14: BLITZ ADMINISTRATIVA | F14: INCUMPLIMIENTO ACTIVIDADES O COMPROMISOS
A15: BLITZ OCCIDENTE | F15: SOLICITUD DE RESULTADOS MICROBIOLÓGICOS
A16: CUNDINAMARCA VETERINARIA | F16: SOLICITUD DEL CLIENTE

Sheet RESPONSABLE 
A1: RESPONSABLE | B1: CARGO
A2: ANDREA HERRERA | B2: DIRECTORA NACIONAL ADMINISTRATIVA
A3: TATIANA RICO | B3: DIRECTOR DE TECNICO REGIONA LLANOS
A4: IVAN PEREIRA | B4: DIRECTOR TECNICO REGIONAL SANTANDER
A5: CARMONA RIOS FRANCISCO JULIAN | B5: DIRECTOR DE CALIDAD REGIONAL ANTIOQUIA
A6: ESTEFANIA MARTINEZ MARTINEZ | B6: DIRECTOR DE CALIDAD REGIONAL COSTA
A7: DORIA NARVÁEZ REYES ENRIQUE | B7: COORDINADOR PRODUCCION PLANTA SOLIDOS NO ESTERILES BOGOTA
A8: DIANA M MUÑOZ M | B8: DIRECTOR DE ASEGURAMIENTO DE CALIDAD NACIONAL
A9: FLOR DE LIZ PINEDA | B9: ANALISTA DE GESTION DE CALIDAD NACIONAL
A10: FRANCISCO ALVAREZ | B10: DIRECTOR TECNICO NACIONAL
A11: CHIRINOS MAESTRE MARY YOHELIN | B11: DIRECTOR DE CALIDAD REGIONAL MARLY
A12: GRANADA ESTRADA HERMES JAMES | B12: DIRECTOR TECNICO REGIONAL ANTIOQUIA
... A29: MANUEL GASCA | B29: Director comercial Zona Occidente
